row,col,percent_valid_snow_pixels,s1_rtc_ds_dims,runoff_onsets_dims,tr_2015,tr_2016,tr_2017,tr_2018,tr_2019,tr_2020,tr_2021,tr_2022,tr_2023,tr_2024,pix_ct_2015,pix_ct_2016,pix_ct_2017,pix_ct_2018,pix_ct_2019,pix_ct_2020,pix_ct_2021,pix_ct_2022,pix_ct_2023,pix_ct_2024,start_time,total_time,success,error_messages
18,205,100.0,"{'latitude': 2048, 'longitude': 2048, 'time': 571}",,,,,,,,,,,,,,,,,,,,,,1752746332.2638779,715.6607723236084,False,"['Chunk and warp failed', 'rasterio._err.CPLE_AppDefinedError: TIFFFillTile:Read error at row 2048, col 4608, tile 131; got 34728 bytes, expected 42337\n\nThe above exception was the direct cause of the following exception:\n\nrasterio._err.CPLE_AppDefinedError: TIFFReadEncodedTile() failed.\n\nThe above exception was the direct cause of the following exception:\n\nTraceback (most recent call last):\n  File ""rasterio/_warp.pyx"", line 630, in rasterio._warp._reproject\n  File ""rasterio/_warp.pyx"", line 630, in rasterio._warp._reproject\n  File ""rasterio/_warp.pyx"", line 638, in rasterio._warp._reproject\n  File ""rasterio/_err.pyx"", line 325, in rasterio._err.StackChecker.exc_wrap_int\nrasterio._err.CPLE_AppDefinedError: IReadBlock failed at X offset 5, Y offset 9: TIFFReadEncodedTile() failed.\n\nThe above exception was the direct cause of the following exception:\n\nTraceback (most recent call last):\n  File ""/home/runner/work/global_snowmelt_runoff_onset/global_snowmelt_runoff_onset/processing/scripts/process_single_tile.py"", line 280, in process_tile_github_actions\n    tile_median_temporal_resolution, tile_pixel_count = dask.compute(\n  File ""/home/runner/miniconda3/envs/global_snowmelt_runoff_onset_actions/lib/python3.10/site-packages/dask/base.py"", line 681, in compute\n    results = schedule(expr, keys, **kwargs)\n  File ""/home/runner/miniconda3/envs/global_snowmelt_runoff_onset_actions/lib/python3.10/site-packages/odc/loader/_builder.py"", line 436, in _dask_loader_tyx\n    _fill_nd_slice(\n  File ""/home/runner/miniconda3/envs/global_snowmelt_runoff_onset_actions/lib/python3.10/site-packages/odc/loader/_builder.py"", line 513, in _fill_nd_slice\n    yx_roi, pix = src.read(cfg, dst_gbox, dst=dst, selection=selection)\n  File ""/home/runner/miniconda3/envs/global_snowmelt_runoff_onset_actions/lib/python3.10/site-packages/odc/loader/_rio.py"", line 115, in read\n    return rio_read(self._src, cfg, dst_geobox, dst=dst, selection=selection)\n  File ""/home/runner/miniconda3/envs/global_snowmelt_runoff_onset_actions/lib/python3.10/site-packages/odc/loader/_rio.py"", line 526, in rio_read\n    raise e\n  File ""/home/runner/miniconda3/envs/global_snowmelt_runoff_onset_actions/lib/python3.10/site-packages/odc/loader/_rio.py"", line 512, in rio_read\n    _rio_read(src, cfg, dst_geobox, prep_dst(dst), selection=selection)\n  File ""/home/runner/miniconda3/envs/global_snowmelt_runoff_onset_actions/lib/python3.10/site-packages/odc/loader/_rio.py"", line 581, in _rio_read\n    return _do_read(\n  File ""/home/runner/miniconda3/envs/global_snowmelt_runoff_onset_actions/lib/python3.10/site-packages/odc/loader/_rio.py"", line 440, in _do_read\n    rasterio.warp.reproject(\n  File ""/home/runner/miniconda3/envs/global_snowmelt_runoff_onset_actions/lib/python3.10/site-packages/rasterio/env.py"", line 410, in wrapper\n    return f(*args, **kwds)\n  File ""/home/runner/miniconda3/envs/global_snowmelt_runoff_onset_actions/lib/python3.10/site-packages/rasterio/warp.py"", line 387, in reproject\n    dest = _reproject(\n  File ""rasterio/_warp.pyx"", line 641, in rasterio._warp._reproject\nrasterio.errors.WarpOperationError: Chunk and warp failed\n']"
